<?xml version="1.0"?>
<robot xmlns:xacro="http://wiki.ros.org/xacro">
  <xacro:macro name="kuka_lbr_iiwa_14_r820" params="prefix">
    <!-- link list -->
    <link name="${prefix}base_link">
      <visual>
        <origin xyz="0 0 0" rpy="0 0 0" />
        <geometry>
          <mesh filename="package://kuka_lbr_iiwa_support/meshes/lbr_iiwa_14_r820/visual/base_link.dae" />
        </geometry>
      </visual>
      <collision>
        <origin xyz="0 0 0" rpy="0 0 0" />
        <geometry>
          <mesh filename="package://kuka_lbr_iiwa_support/meshes/lbr_iiwa_14_r820/collision/base_link.stl" />
        </geometry>
      </collision>
    <inertial>
			<origin xyz="0 0 0" rpy="0 0 0"/>
			<mass value="5" />
			<inertia  ixx="0.05" ixy="0.0" ixz="0.0"
                iyy="0.06" iyz="0.0"
                izz="0.03" />
    </inertial>
    </link>
    <link name="${prefix}link_1">
      <visual>
        <origin xyz="0 0 0" rpy="0 0 0" />
        <geometry>
          <mesh filename="package://kuka_lbr_iiwa_support/meshes/lbr_iiwa_14_r820/visual/link_1.dae" />
        </geometry>
      </visual>
      <collision>
        <origin xyz="0 0 0" rpy="0 0 0" />
        <geometry>
          <mesh filename="package://kuka_lbr_iiwa_support/meshes/lbr_iiwa_14_r820/collision/link_1.stl" />
        </geometry>
      </collision>
    <inertial>
			<origin xyz="0 0 0" rpy="0 0 0"/>
			<mass value="4" />
			<inertia  ixx="0.1" ixy="0.0" ixz="0.0"
                iyy="0.09" iyz="0.0"
                izz="0.02" />
    </inertial>
    </link>
    <link name="${prefix}link_2">
      <visual>
        <origin xyz="0 0 0" rpy="0 0 0" />
        <geometry>
          <mesh filename="package://kuka_lbr_iiwa_support/meshes/lbr_iiwa_14_r820/visual/link_2.dae" />
        </geometry>
      </visual>
      <collision>
        <origin xyz="0 0 0" rpy="0 0 0" />
        <geometry>
          <mesh filename="package://kuka_lbr_iiwa_support/meshes/lbr_iiwa_14_r820/collision/link_2.stl" />
        </geometry>
      </collision>
    <inertial>
			<origin xyz="0 0 0" rpy="0 0 0"/>
			<mass value="4" />
			<inertia  ixx="0.05" ixy="0.0" ixz="0.0"
                iyy="0.018" iyz="0.0"
                izz="0.044" />
    </inertial>
    </link>
    <link name="${prefix}link_3">
      <visual>
        <origin xyz="0 0 0" rpy="0 0 0" />
        <geometry>
          <mesh filename="package://kuka_lbr_iiwa_support/meshes/lbr_iiwa_14_r820/visual/link_3.dae" />
        </geometry>
      </visual>
      <collision>
        <origin xyz="0 0 0" rpy="0 0 0" />
        <geometry>
          <mesh filename="package://kuka_lbr_iiwa_support/meshes/lbr_iiwa_14_r820/collision/link_3.stl" />
        </geometry>
      </collision>
    <inertial>
			<origin xyz="0 0 0" rpy="0 0 0"/>
			<mass value="3" />
			<inertia  ixx="0.08" ixy="0.0" ixz="0.0"
                iyy="0.075" iyz="0.0"
                izz="0.01" />
    </inertial>
    </link>
    <link name="${prefix}link_4">
      <visual>
        <origin xyz="0 0 0" rpy="0 0 0" />
        <geometry>
          <mesh filename="package://kuka_lbr_iiwa_support/meshes/lbr_iiwa_14_r820/visual/link_4.dae" />
        </geometry>
      </visual>
      <collision>
        <origin xyz="0 0 0" rpy="0 0 0" />
        <geometry>
          <mesh filename="package://kuka_lbr_iiwa_support/meshes/lbr_iiwa_14_r820/collision/link_4.stl" />
        </geometry>
      </collision>
    <inertial>
			<origin xyz="0 0 0" rpy="0 0 0"/>
			<mass value="2.7" />
			<inertia  ixx="0.03" ixy="0.0" ixz="0.0"
                iyy="0.01" iyz="0.0"
                izz="0.029" />
    </inertial>
    </link>
    <link name="${prefix}link_5">
      <visual>
        <origin xyz="0 0 0" rpy="0 0 0" />
        <geometry>
          <mesh filename="package://kuka_lbr_iiwa_support/meshes/lbr_iiwa_14_r820/visual/link_5.dae" />
        </geometry>
      </visual>
      <collision>
        <origin xyz="0 0 0" rpy="0 0 0" />
        <geometry>
          <mesh filename="package://kuka_lbr_iiwa_support/meshes/lbr_iiwa_14_r820/collision/link_5.stl" />
        </geometry>
      </collision>
    <inertial>
			<origin xyz="0 0 0" rpy="0 0 0"/>
			<mass value="1.7" />
			<inertia  ixx="0.02" ixy="0.0" ixz="0.0"
                iyy="0.018" iyz="0.0"
                izz="0.005" />
    </inertial>
    </link>
    <link name="${prefix}link_6">
      <visual>
        <origin xyz="0 0 0" rpy="0 0 0" />
        <geometry>
          <mesh filename="package://kuka_lbr_iiwa_support/meshes/lbr_iiwa_14_r820/visual/link_6.dae" />
        </geometry>
      </visual>
      <collision>
        <origin xyz="0 0 0" rpy="0 0 0" />
        <geometry>
          <mesh filename="package://kuka_lbr_iiwa_support/meshes/lbr_iiwa_14_r820/collision/link_6.stl" />
        </geometry>
      </collision>
    <inertial>
			<origin xyz="0 0 0" rpy="0 0 0"/>
			<mass value="1.8" />
			<inertia  ixx="0.005" ixy="0.0" ixz="0.0"
                iyy="0.0036" iyz="0.0"
                izz="0.0047" />
    </inertial>
    </link>
    <link name="${prefix}link_7">
      <visual>
        <origin xyz="0 0 0" rpy="0 0 0" />
        <geometry>
          <mesh filename="package://kuka_lbr_iiwa_support/meshes/lbr_iiwa_14_r820/visual/link_7.dae" />
        </geometry>
      </visual>
      <collision>
        <origin xyz="0 0 0" rpy="0 0 0" />
        <geometry>
          <mesh filename="package://kuka_lbr_iiwa_support/meshes/lbr_iiwa_14_r820/collision/link_7.stl" />
        </geometry>
      </collision>
    <inertial>
			<origin xyz="0 0 0" rpy="0 0 0"/>
			<mass value="0.3" />
			<inertia  ixx="0.001" ixy="0.0" ixz="0.0"
                iyy="0.001" iyz="0.0"
                izz="0.001" />
    </inertial>
    </link>
    <link name="${prefix}tool0" />
    <!-- end of link list -->

    <!-- joint list -->
    <joint name="${prefix}joint_a1" type="revolute">
      <origin xyz="0 0 0" rpy="0 0 0" />
      <parent link="${prefix}base_link" />
      <child link="${prefix}link_1" />
      <axis xyz="0 0 1" />
      <limit lower="-2.9668" upper="2.9668" effort="0" velocity="1.4834" />
    </joint>
    <joint name="${prefix}joint_a2" type="revolute">
      <origin xyz="-0.00043624 0 0.36" rpy="0 0 0" />
      <parent link="${prefix}link_1" />
      <child link="${prefix}link_2" />
      <axis xyz="0 1 0" />
      <limit lower="-2.0942" upper="2.0942" effort="0" velocity="1.4834" />
    </joint>
    <joint name="${prefix}joint_a3" type="revolute">
      <origin xyz="0 0 0" rpy="0 0 0" />
      <parent link="${prefix}link_2" />
      <child link="${prefix}link_3" />
      <axis xyz="0 0 1" />
      <limit lower="-2.9668" upper="2.9668" effort="0" velocity="1.7452" />
    </joint>
    <joint name="${prefix}joint_a4" type="revolute">
      <origin xyz="0.00043624 0 0.42" rpy="0 0 0" />
      <parent link="${prefix}link_3" />
      <child link="${prefix}link_4" />
      <axis xyz="0 -1 0" />
      <limit lower="-2.0942" upper="2.0942" effort="0" velocity="1.3089" />
    </joint>
    <joint name="${prefix}joint_a5" type="revolute">
      <origin xyz="0 0 0" rpy="0 0 0" />
      <parent link="${prefix}link_4" />
      <child link="${prefix}link_5" />
      <axis xyz="0 0 1" />
      <limit lower="-2.9668" upper="2.9668" effort="0" velocity="2.2688" />
    </joint>
    <joint name="${prefix}joint_a6" type="revolute">
      <origin xyz="0 0 0.4" rpy="0 0 0" />
      <parent link="${prefix}link_5" />
      <child link="${prefix}link_6" />
      <axis xyz="0 1 0" />
      <limit lower="-2.0942" upper="2.0942" effort="0" velocity="2.356" />
    </joint>
    <joint name="${prefix}joint_a7" type="revolute">
      <origin xyz="0 0 0" rpy="0 0 0" />
      <parent link="${prefix}link_6" />
      <child link="${prefix}link_7" />
      <axis xyz="0 0 1" />
      <limit lower="-3.0541" upper="3.0541" effort="0" velocity="2.356" />
    </joint>
    <joint name="${prefix}joint_a7-tool0" type="fixed">
      <origin xyz="0 0 0.126" rpy="0 0 0" />
      <parent link="${prefix}link_7" />
      <child link="${prefix}tool0" />
      <axis xyz="0 0 0" />
    </joint>
    <!-- end of joint list -->

    <!-- ROS base_link to KUKA $ROBROOT coordinate system transform -->
    <link name="${prefix}base" />
    <joint name="${prefix}base_link-base" type="fixed">
      <origin xyz="0 0 0" rpy="0 0 0"/>
      <parent link="${prefix}base_link"/>
      <child link="${prefix}base"/>
    </joint>
  </xacro:macro>
</robot>

